<?xml version="1.0" encoding="utf-8"?>
<!-- This URDF was automatically created by SolidWorks to URDF Exporter! Originally created by Stephen Brawner (brawner@gmail.com) 
     Commit Version: 1.6.0-4-g7f85cfe  Build Version: 1.6.7995.38578
     For more information, please see http://wiki.ros.org/sw_urdf_exporter -->
<robot
  name="rover_mesh_2">
  <link
    name="base_link">
    <inertial>
      <origin
        xyz="-0.0015644 -0.049703 0.09434"
        rpy="0 0 0" />
      <mass
        value="16.036" />
      <inertia
        ixx="0.17769"
        ixy="0.0006185"
        ixz="-0.00012306"
        iyy="0.13244"
        iyz="-0.00052457"
        izz="0.2638" />
    </inertial>
    <visual>
      <origin
        xyz="0 0 0"
        rpy="0 0 0" />
      <geometry>
        <mesh
          filename="package://rover_mesh_2/meshes/base_link.STL" />
      </geometry>
      <material
        name="">
        <color
          rgba="0.75294 0.75294 0.75294 1" />
      </material>
    </visual>
    <collision>
      <origin
        xyz="0 0 0"
        rpy="0 0 0" />
      <geometry>
        <mesh
          filename="package://rover_mesh_2/meshes/base_link.STL" />
      </geometry>
    </collision>
  </link>
  <link
    name="left_rear_wheel_link">
    <inertial>
      <origin
        xyz="0.00011831 1.7454E-10 -5.3989E-07"
        rpy="0 0 0" />
      <mass
        value="1.3852" />
      <inertia
        ixx="0.0060867"
        ixy="-1.3047E-10"
        ixz="5.0163E-08"
        iyy="0.0033173"
        iyz="5.842E-11"
        izz="0.0033173" />
    </inertial>
    <visual>
      <origin
        xyz="0 0 0"
        rpy="0 0 0" />
      <geometry>
        <mesh
          filename="package://rover_mesh_2/meshes/left_rear_wheel_link.STL" />
      </geometry>
      <material
        name="">
        <color
          rgba="0.79216 0.81961 0.93333 1" />
      </material>
    </visual>
    <collision>
      <origin
        xyz="0 0 0"
        rpy="0 0 0" />
      <geometry>
        <mesh
          filename="package://rover_mesh_2/meshes/left_rear_wheel_link.STL" />
      </geometry>
    </collision>
  </link>
  <joint
    name="left_rear_wheel_joint"
    type="continuous">
    <origin
      xyz="-0.41008 0.4318 -0.2667"
      rpy="0 0 0" />
    <parent
      link="base_link" />
    <child
      link="left_rear_wheel_link" />
    <axis
      xyz="-1 0 0" />
  </joint>
  <link
    name="right_rear_wheel_link">
    <inertial>
      <origin
        xyz="-0.00011831 6.4147E-09 -5.4762E-07"
        rpy="0 0 0" />
      <mass
        value="1.3852" />
      <inertia
        ixx="0.0060867"
        ixy="-1.5161E-10"
        ixz="-5.0138E-08"
        iyy="0.0033173"
        iyz="-1.6819E-11"
        izz="0.0033173" />
    </inertial>
    <visual>
      <origin
        xyz="0 0 0"
        rpy="0 0 0" />
      <geometry>
        <mesh
          filename="package://rover_mesh_2/meshes/right_rear_wheel_link.STL" />
      </geometry>
      <material
        name="">
        <color
          rgba="0.79216 0.81961 0.93333 1" />
      </material>
    </visual>
    <collision>
      <origin
        xyz="0 0 0"
        rpy="0 0 0" />
      <geometry>
        <mesh
          filename="package://rover_mesh_2/meshes/right_rear_wheel_link.STL" />
      </geometry>
    </collision>
  </link>
  <joint
    name="right_rear_wheel_joint"
    type="continuous">
    <origin
      xyz="0.41014 0.4318 -0.2667"
      rpy="0 0 0" />
    <parent
      link="base_link" />
    <child
      link="right_rear_wheel_link" />
    <axis
      xyz="1 0 0" />
  </joint>
  <link
    name="left_middle_wheel_link">
    <inertial>
      <origin
        xyz="0.00011831 -4.1078E-07 -3.6496E-07"
        rpy="0 0 0" />
      <mass
        value="1.3852" />
      <inertia
        ixx="0.0060867"
        ixy="3.7938E-08"
        ixz="3.2773E-08"
        iyy="0.0033173"
        iyz="-8.2013E-09"
        izz="0.0033173" />
    </inertial>
    <visual>
      <origin
        xyz="0 0 0"
        rpy="0 0 0" />
      <geometry>
        <mesh
          filename="package://rover_mesh_2/meshes/left_middle_wheel_link.STL" />
      </geometry>
      <material
        name="">
        <color
          rgba="0.79216 0.81961 0.93333 1" />
      </material>
    </visual>
    <collision>
      <origin
        xyz="0 0 0"
        rpy="0 0 0" />
      <geometry>
        <mesh
          filename="package://rover_mesh_2/meshes/left_middle_wheel_link.STL" />
      </geometry>
    </collision>
  </link>
  <joint
    name="left_middle_wheel_joint"
    type="continuous">
    <origin
      xyz="-0.41008 0 -0.2667"
      rpy="0 0 0" />
    <parent
      link="base_link" />
    <child
      link="left_middle_wheel_link" />
    <axis
      xyz="-1 0 0" />
  </joint>
  <link
    name="right_middle_wheel_link">
    <inertial>
      <origin
        xyz="-0.00011831 -4.1147E-07 -3.4979E-07"
        rpy="0 0 0" />
      <mass
        value="1.3852" />
      <inertia
        ixx="0.0060867"
        ixy="-3.8106E-08"
        ixz="-3.2623E-08"
        iyy="0.0033173"
        iyz="-8.4377E-09"
        izz="0.0033173" />
    </inertial>
    <visual>
      <origin
        xyz="0 0 0"
        rpy="0 0 0" />
      <geometry>
        <mesh
          filename="package://rover_mesh_2/meshes/right_middle_wheel_link.STL" />
      </geometry>
      <material
        name="">
        <color
          rgba="0.79216 0.81961 0.93333 1" />
      </material>
    </visual>
    <collision>
      <origin
        xyz="0 0 0"
        rpy="0 0 0" />
      <geometry>
        <mesh
          filename="package://rover_mesh_2/meshes/right_middle_wheel_link.STL" />
      </geometry>
    </collision>
  </link>
  <joint
    name="right_middle_wheel_joint"
    type="continuous">
    <origin
      xyz="0.41014 0 -0.2667"
      rpy="0 0 0" />
    <parent
      link="base_link" />
    <child
      link="right_middle_wheel_link" />
    <axis
      xyz="1 0 0" />
  </joint>
  <link
    name="left_front_wheel_link">
    <inertial>
      <origin
        xyz="0.00015521 9.0026E-09 -5.4751E-07"
        rpy="0 0 0" />
      <mass
        value="1.3852" />
      <inertia
        ixx="0.0060867"
        ixy="-1.5155E-10"
        ixz="5.0139E-08"
        iyy="0.0033173"
        iyz="1.7921E-11"
        izz="0.0033173" />
    </inertial>
    <visual>
      <origin
        xyz="0 0 0"
        rpy="0 0 0" />
      <geometry>
        <mesh
          filename="package://rover_mesh_2/meshes/left_front_wheel_link.STL" />
      </geometry>
      <material
        name="">
        <color
          rgba="0.79216 0.81961 0.93333 1" />
      </material>
    </visual>
    <collision>
      <origin
        xyz="0 0 0"
        rpy="0 0 0" />
      <geometry>
        <mesh
          filename="package://rover_mesh_2/meshes/left_front_wheel_link.STL" />
      </geometry>
    </collision>
  </link>
  <joint
    name="left_front_wheel_joint"
    type="continuous">
    <origin
      xyz="-0.37202 -0.43504 -0.26758"
      rpy="0 0 0" />
    <parent
      link="base_link" />
    <child
      link="left_front_wheel_link" />
    <axis
      xyz="1 0 0" />
  </joint>
  <link
    name="right_front_wheel_link">
    <inertial>
      <origin
        xyz="0 0 0"
        rpy="0 0 0" />
      <mass
        value="0" />
      <inertia
        ixx="0"
        ixy="0"
        ixz="0"
        iyy="0"
        iyz="0"
        izz="0" />
    </inertial>
    <visual>
      <origin
        xyz="0 0 0"
        rpy="0 0 0" />
      <geometry>
        <mesh
          filename="package://rover_mesh_2/meshes/right_front_wheel_link.STL" />
      </geometry>
      <material
        name="">
        <color
          rgba="1 1 1 1" />
      </material>
    </visual>
    <collision>
      <origin
        xyz="0 0 0"
        rpy="0 0 0" />
      <geometry>
        <mesh
          filename="package://rover_mesh_2/meshes/right_front_wheel_link.STL" />
      </geometry>
    </collision>
  </link>
  <joint
    name="right_front_wheel_joint"
    type="continuous">
    <origin
      xyz="0.37204 -0.43504 -0.26758"
      rpy="0 0 0" />
    <parent
      link="base_link" />
    <child
      link="right_front_wheel_link" />
    <axis
      xyz="1 0 0" />
  </joint>
</robot>